Workbook
Name CurrentStatus: '[1]ADMIN TAB - DO NOT TOUCH'!$A$24:$A$33
Name ExitReason: '[1]ADMIN TAB - DO NOT TOUCH'!$A$88:$A$102
Name FY20SCHOOLS: '[1]ADMIN TAB - DO NOT TOUCH'!$A$5:$A$20
Name GeninfoWhole: 'GenInfo (2)'!$F$8:$IL$94
Name Grades: '[1]ADMIN TAB - DO NOT TOUCH'!$A$106:$A$112
Name HiatusHB: '[1]ADMIN TAB - DO NOT TOUCH'!$A$64:$A$66
Name ogchecklist: #REF!
Name oggeninfo: #REF!
Name Placement: '[1]ADMIN TAB - DO NOT TOUCH'!$A$43:$A$52
Name Race: '[1]ADMIN TAB - DO NOT TOUCH'!$A$56:$A$60
Name ReferralEnd: '[1]ADMIN TAB - DO NOT TOUCH'!$A$37:$A$39
Name ReferralReason: '[1]ADMIN TAB - DO NOT TOUCH'!$A$70:$A$84
Name TranYouthStatus: '[1]ADMIN TAB - DO NOT TOUCH'!$D$4:$D$9

Sheet GenInfo (2)
K1: REFERRAL | U1: ENTRY/EXIT/DISCHARGE | AA1: CASEWORKER INFO | AK1: DEMOGRAPHICS AND MOBILITY | BD1: ATTENDANCE/TRUANCY/ACE BREAKDOWN | BN1: ATTENDANCE / ACE QTR 1 | CP1: ATTENDANCE/ACE QTR 2 | DT1: ATTENDANCE/ACE QTR 3 | EX1: ATTENDANCE/ACE QTR 4 | GE1: CREDIT GAINS | GP1: CHECKLIST | IM1: SKILLS GAINS/STAR SCORES | LM1: DO NOT USE COLUMNS RIGHT OF THIS MARKER | LN1: ADMIN 1 (DO NOT TOUCH) | LQ1: ADMIN 2 (DO NOT TOUCH) | LT1: ADMIN 3 (DO NOT TOUCH) | LW1: ADMIN 4 (DO NOT TOUCH) | LZ1: ADMIN 5 (DO NOT TOUCH) | MC1: ADMIN 6 (DO NOT TOUCH) | MF1: ADMIN 7 (DO NOT TOUCH) | MI1: ADMIN 8 (DO NOT TOUCH) | ML1: ADMIN 9 (DO NOT TOUCH) | MO1: ADMIN 10 (DO NOT TOUCH) | MR1: ADMIN 11 (DO NOT TOUCH) | MU1: ADMIN 12 (DO NOT TOUCH) | MX1: ADMIN 13 (DO NOT TOUCH) | NA1: ADMIN 14 (DO NOT TOUCH) | ND1: ADMIN 15 (DO NOT TOUCH)
GP4: ENROLLMENT DOCUMENTS | HL4: STAR SCORES | HR4: REPORT CARDS/TRANSCRIPTS | ID4: ACE PACKET DOCUMENTS
A5: Fields to the right filled in Blue are data originally obtained from the YS3 Referral form | C5: LAST NAME | D5: FIRST NAME | E5: SCHOOL | F5: DCFS ID# | G5: CURRENT STATUS | H5: IF OTHER, PLEASE EXPLAIN | I5: EMAIL ADDRESS | J5: PHONE # | L5: DATE REFERRED TO ASN | M5: DATE APPROVED BY DCFS | N5: PUT "X" IF OFFICIALLY PENDING | O5: PENDING MONTH | P5: OFFICIALLY PENDING START | Q5: OFFICIALLY PENDING END | R5: REFERRAL END STATUS | S5: REFERRAL END STATUS DATE | T5: IF NOT ACCEPTED OR NOT APPROVED BY DCFS, PLEASE PROVIDE REASON | V5: ENROLLMENT DATE | W5: SCHOOL EXIT DATE | X5: SCHOOL EXIT REASON | Y5: PROGRAM DISCHARGE DATE | Z5: PROGRAM DISCHARGE REASON | AB5: Current Caseworker Name | AC5: Phone | AD5: Email | AE5: Agency | AF5: Street Address | AG5: Unit / Suite # | AH5: City | AI5: State | AJ5: Zip | AL5: ENTRY AGE | AM5: CURRENT | AN5: DOB | AO5: Months until 21 | AP5: Gender | AR5: LIVING SITUATION | AS5: Number of Previous HS | AT5: Number of DAYS out of school | AU5: How old when case was open | AV5: Number of Placements | AW5: DAYS at current placement | AX5: Grade at Entry | AY5: SpecEd | AZ5: TP Entry | BA5: TP To Date | BB5: DUE DATE IF PREGNANT? | BC5: # CHILDREN | BE5: TOTAL MTHS POSSIBLE ATTENDANCE | BF5: TOTAL MONTHS ATTENDED AT LEAST 1 DAY | BG5: TOTAL MONTHS TRUANT | BH5: ATTENDANCE MONTHLY AVG % | BI5: % MONTHS TRUANT | BJ5: # MONTHS PARTICIPATED IN ACE | BK5: % MONTHS ACE PARTICIPATION | BL5: TOTAL HOURS ACE | BM5: TOTAL $ EARNED | BN5: JULY | BX5: AUGUST | CF5: SEPTEMBER | CP5: OCTOBER | CZ5: NOVEMBER | DJ5: DECEMBER | DT5: JANUARY | ED5: FEBRUARY | EN5: MARCH | EX5: APRIL | FI5: MAY | FT5: JUNE | GF5: CREDITS AT START OF FY | GG5: GRADE LEVEL AT START OF FY | GH5: SUMMER | GI5: QTR 1 | GJ5: QTR 2 | GK5: TOTAL GAINED SUMMER & SEMESTER 1 | GL5: QTR 3 | GM5: QTR 4 | GN5: TOTAL GAINED SEMESTER 2 | GO5: CREDITS AT END OF FY | GQ5: Referral Form | GR5: Entry Student Review | GS5: Trial Consent Form | GT5: Birth Certificate | GU5: Soc Sec Card | GV5: State ID / Drivers License | GW5: Medical Card | GX5: IEP (if needed) | GY5: Entry STAR Math | GZ5: Entry STAR Reading | HA5: Previous HS Transcripts (all) | HB5: Entry School Transcript | HC5: Exit Forms | HD5: Exit Proof | HE5: Exit Student Review | HF5: Client Satisfaction Survey | HG5: Casey Life Skills | HH5: Staffing Forms | HI5: Staffing Follow-up Forms | HJ5: Hiatus Form | HK5: Homebound Documentation | HL5: STAR-M (Pre - Sept/Oct - Due 10/18/19) | HM5: STAR-M (Mid - Dec/Jan - Due 1/15/20) | HN5: STAR-M (Post - April/May - Due 5/30/19) | HO5: STAR-R (Pre - Sept/Oct - Due 10/18/19) | HP5: STAR-R (Mid - Dec/Jan - Due 1/15/20) | HQ5: STAR-R (Post - April/May - Due 5/30/19) | HR5: Summer Report Card | HS5: Quarter 1 - Report Card | HT5: Quarter 2 - Report Card | HU5: Quarter 3 - Report Card | HV5: Quarter 4 - Report Card | HW5: Summer Updated Transcript (Due 10/17/17) | HX5: 1st Semester Transcript (Due 2/1/2018) | HY5: 2nd Semester Transcript (Due 6/15/2018) | HZ5: Student Review 1 (Due 10/17/19) | IA5: Student Review 2 (Due 2/13/20) | IB5: Student Review 3 (Due 6/26/20) | IC5: Annual High School Academic Plan | ID5: Year | IE5: Enrollment Checklist | IF5: Employee Action Form | IG5: I-9 | IH5: W-4 Federal | II5: W-4 Illinois | IJ5: License or ID | IK5: SSC or BC | IL5: SUMMER ENROLLMENT CHECKLIST | IO5: MATH | JC5: READING
AQ6: Ethn | BN6: HIATUS/HB STATUS? | BO6: HIATUS/HB START | BP6: HIATUS/HB END | BQ6: POSSIBLE DAYS ATTENDED | BR6: ATTENDED DAYS | BS6: ATTENDANCE % | BT6: ACE WORK HRS 1 | BU6: ACE HRS 2 | BV6: TOTAL ACE HRS | BW6: ACE $ EARNED | BX6: HIATUS/HB STATUS? | BY6: HIATUS/HB START DATE | BZ6: HIATUS/HB END DATE | CA6: POSSIBLE DAYS ATTENDED | CB6: ATTENDED DAYS | CC6: ATTENDANCE % | CD6: ACE WORK HRS | CE6: ACE $ EARNED | CF6: HIATUS/HB STATUS? | CG6: HIATUS/HB START DATE | CH6: HIATUS/HB END DATE | CI6: POSSIBLE DAYS ATTENDED | CJ6: ATTENDED DAYS | CK6: ATTENDANCE % | CL6: ACE 1 | CM6: ACE 2 | CN6: ACE TOTAL | CO6: ACE $ EARNED | CP6: HIATUS/HB STATUS? | CQ6: HIATUS/HB START DATE | CR6: HIATUS/HB END DATE | CS6: POSSIBLE DAYS ATTENDED | CT6: ATTENDED DAYS | CU6: ATTENDANCE % | CV6: ACE 1 HRS | CW6: ACE 2 HRS | CX6: TOTAL ACE HRS | CY6: ACE $ | CZ6: HIATUS/HB STATUS? | DA6: HIATUS/HB START DATE | DB6: HIATUS/HB END DATE | DC6: POSSIBLE DAYS ATTENDED | DD6: ATTENDED DAYS | DE6: ATTENDANCE % | DF6: ACE 1 | DG6: ACE 2 | DH6: ACE HRS | DI6: ACE $ | DJ6: HIATUS/HB STATUS? | DK6: HIATUS/HB START DATE | DL6: HIATUS/HB END DATE | DM6: POSSIBLE DAYS ATTENDED | DN6: ATTENDED DAYS | DO6: ATTENDANCE % | DP6: ACE 1 | DQ6: ACE 2 | DR6: ACE HRS | DS6: ACE TOTAL | DT6: HIATUS/HB STATUS? | DU6: HIATUS/HB START DATE | DV6: HIATUS/HB END DATE | DW6: POSSIBLE DAYS ATTENDED | DX6: ATTENDED DAYS | DY6: ATTENDANCE % | DZ6: ACE 1 | EA6: ACE 2 | EB6: TOTAL ACE HOURS | EC6: TOTAL ACE PAY | ED6: HIATUS/HB STATUS? | EE6: HIATUS/HB START DATE | EF6: HIATUS/HB END DATE | EG6: POSSIBLE DAYS ATTENDED | EH6: ATTENDED DAYS | EI6: ATTENDANCE % | EJ6: ACE 1 HRS | EK6: ACE 2 HRS | EL6: TOTAL ACE HRS | EM6: ACE $ | EN6: HIATUS/HB STATUS? | EO6: HIATUS/HB START DATE | EP6: HIATUS/HB END DATE | EQ6: POSSIBLE DAYS ATTENDED | ER6: ATTENDED DAYS | ES6: ATTENDANCE % | ET6: ACE 1 HRS | EU6: ACE 2 HRS | EV6: TOTAL ACE HRS | EW6: ACE $ | EX6: HIATUS/HB STATUS? | EY6: HIATUS/HB START DATE | EZ6: HIATUS/HB END DATE | FA6: POSSIBLE DAYS ATTENDED | FB6: ATTENDED DAYS | FC6: ATTENDANCE % | FD6: TUTORING | FE6: COUNSELING | FF6: AFTER SCHOOL | FG6: WORK | FH6: ACE TOTAL | FI6: HIATUS/HB STATUS? | FJ6: HIATUS/HB START DATE | FK6: HIATUS/HB END DATE | FL6: POSSIBLE DAYS ATTENDED | FM6: ATTENDED DAYS | FN6: ATTENDANCE % | FO6: TUTORING | FP6: COUNSELING | FQ6: AFTER SCHOOL | FR6: WORK | FS6: ACE TOTAL | FT6: HIATUS/HB STATUS? | FU6: HIATUS/HB START DATE | FV6: HIATUS/HB END DATE | FW6: POSSIBLE DAYS ATTENDED | FX6: ATTENDED DAYS | FY6: ATTENDANCE % | FZ6: TUTORING | GA6: COUNSELING | GB6: AFTER SCHOOL | GC6: WORK | GD6: ACE TOTAL | IN6: ENTRY | IO6: JULY | IP6: AUG | IQ6: SEPT | IR6: OCT | IS6: NOV | IT6: DEC | IU6: JAN | IV6: FEB | IW6: MARCH | IX6: APRIL | IY6: MAY | IZ6: JUNE | JA6: # OF TESTS | JB6: GAIN | JC6: ENTRY | JD6: JULY7 | JE6: AUG8 | JF6: SEPT9 | JG6: OCT10 | JH6: NOV11 | JI6: DEC12 | JJ6: JAN13 | JK6: FEB14 | JL6: MARCH15 | JM6: APRIL16 | JN6: MAY17 | JO6: JUNE2 | JP6: # TESTS | JQ6: GAIN | JR6: 32 | JS6: 33 | JT6: 34 | JU6: 35 | JV6: 36 | JW6: 37 | JX6: 38 | JY6: 39 | JZ6: 40 | KA6: 41 | KB6: 42 | KC6: 43 | KD6: 44 | KE6: 45 | KF6: 46 | KG6: 47 | KH6: 48 | KI6: 49 | KJ6: 50 | KK6: 51 | KL6: 52 | KM6: 53 | KN6: 55 | KO6: 56 | KP6: 57 | KQ6: 58 | KR6: 59 | KS6: 60 | KT6: 61 | KU6: 62 | KV6: 63 | KW6: 64 | KX6: 65 | KY6: 66 | KZ6: 67 | LA6: 68 | LB6: 69 | LC6: 70 | LD6: 71 | LE6: 72 | LF6: 73 | LG6: 74 | LH6: 75 | LI6: 76 | LJ6: 77 | LK6: 78 | LL6: 79
A7: Selection | B7: Sorting
A8: x | B8: 4 | C8: Sample01 | D8: Student01 | E8: Antonia Pantoja Hs | F8: N5996686 | G8: Enrolled | I8: SSample01@asn.com | J8: 773-555-0001 | V8: 43549 | W8: Current | AB8: Megan Garcia | AC8: 847-404-0878 | AD8: megan.burgess-garcia@illinois.gov | AE8: DCFS | AF8: 1755 Lake Cook Rd. | AG8: F15 | AH8: Deerfield | AI8: IL | AJ8: 60015 | AL8: =IFERROR(DATEDIF(AN8,V8,"y"),"") -> 16 | AM8: =IFERROR(DATEDIF($AN8,TODAY(),"y"),"") -> 18 | AN8: 37687 | AO8: =IFERROR(DATEDIF(TODAY(),EDATE(AN8,(12*21)),"m"),"") -> 25 | AP8: F | AQ8: Latino/Hispanic | AR8: Foster home | AS8: 1 | AT8: 90 | AU8: 15 | AV8: 2 | AW8: 7 | AX8: Freshman | AY8: No | AZ8: No | BA8: No | BE8: =IFERROR(COUNTIF(CI8,">0")+COUNTIF(CS8,">0")+COUNTIF(DC8,">0")+COUNTIF(DM8,">0")+COUNTIF(DW8,">0")+COUNTIF(EG8,">0")," ") -> 6 | BF8: =IFERROR(COUNTIF(CJ8,">0")+COUNTIF(CT8,">0")+COUNTIF(DD8,">0")+COUNTIF(DN8,">0")+COUNTIF(DX8,">0")+COUNTIF(EH8,">0")," ") -> 6 | BG8: =IFERROR(COUNTIF(CK8,"<49.5%")+COUNTIF(CU8,"<49.5%")+COUNTIF(DE8,"<49.5%")+COUNTIF(DO8,"<49.5%")+COUNTIF(DY8,"<49.5%")+COUNTIF(EI8,"<49.5%")," ") -> 0 | BH8: =IFERROR(AVERAGE(CK8,CU8,DE8,DO8,DY8,EI8)," ") -> 1 | BI8: =IFERROR(BG8/BE8," ") -> 0 | BJ8: =IFERROR(COUNTIF(CN8,">0")+COUNTIF(CW8,">0")+COUNTIF(DH8,">0")+COUNTIF(DR8,">0")+COUNTIF(EB8,">0")+COUNTIF(EL8,">0")," ") -> 6 | BK8: =IFERROR(BJ8/BE8," ") -> 1 | BL8: =IFERROR(SUM(BV8,CD8,CN8,CW8,DH8,DR8,EB8,EL8),"") -> 186 | BM8: =IFERROR(SUM(BW8,CE8,CO8,CX8,DI8,DS8,EC8,EM8),"") -> 1711 | BQ8: 18 | BR8: 18 | BS8: =IFERROR(BR8/BQ8," ") -> 1 | BT8: 30 | BU8: 30 | BV8: 60 | BW8: 780 | CA8: 7 | CB8: 7 | CC8: =IFERROR(CB8/CA8," ") -> 1 | CD8: 30 | CE8: 390 | CI8: 18 | CJ8: 18 | CK8: =IFERROR(CJ8/CI8," ") -> 1 | CL8: 2 | CM8: 0 | CN8: 2 | CO8: 12 | CS8: 22 | CT8: 22 | CU8: =IFERROR(CT8/CS8," ") -> 1 | CV8: 10 | CW8: 9 | CX8: 19 | CY8: 114 | DC8: 15 | DD8: 15 | DE8: =IFERROR(DD8/DC8," ") -> 1 | DF8: 6 | DG8: 7 | DH8: 13 | DI8: 78 | DM8: 15 | DN8: 15 | DO8: =IFERROR(DN8/DM8," ") -> 1 | DP8: 12 | DQ8: 8 | DR8: 20 | DS8: 120 | DW8: 17 | DX8: 17 | DY8: =IFERROR(DX8/DW8," ") -> 1 | DZ8: 13 | EA8: 13 | EB8: 26 | EC8: 156 | EG8: 17 | EH8: 17 | EI8: =IFERROR(EH8/EG8," ") -> 1 | EJ8: 13 | EK8: 13 | EL8: 26 | EM8: 156 | EQ8: 10 | ER8: 10 | ES8: =IFERROR(ER8/EQ8," ") -> 1 | ET8: 13 | EV8: 13 | EW8: 78 | FC8: =IFERROR(FB8/FA8," ") | FH8: =SUM(FD8:FG8) -> 0 | FN8: =IFERROR(FM8/FL8," ") | FS8: =SUM(FO8:FR8) -> 0 | FY8: =IFERROR(FX8/FW8," ") | GD8: =SUM(FZ8:GC8) -> 0 | GF8: 12 | GG8: Senior | GI8: 3.25 | GJ8: 2.75 | GK8: =IFERROR(SUM(GH8:GJ8)," ") -> 6 | GL8: 1 | GN8: =IFERROR(SUM(GL8:GM8)," ") -> 1 | GO8: =IFERROR(GF8+GK8+GN8," ") -> 19 | GQ8: x | GR8: x | GS8: x | GT8: x | GU8: x | GV8: m | GW8: x | GX8: no | GY8: =IFERROR(IF(IN8>0,"X",""),"") -> X | GZ8: =IFERROR(IF(JC8>0,"X",""),"") -> X | HA8: x | HB8: m | HC8: 0 | HD8: 0 | HE8: 0 | HF8: x | HG8: x | HH8: 0 | HI8: 0 | HJ8: 0 | HK8: 0 | HL8: =IFERROR(IF(OR(IQ8>0,IR8>0,IS8>0),"x",""),"") -> x | HM8: =IFERROR(IF(OR(IT8>0,IU8>0,IV8>0),"x",""),"") | HN8: n/a | HO8: =IFERROR(IF(OR(JE8>0,JF8>0,JG8>0,JH8>0),"x",""),"") -> x | HP8: =IFERROR(IF(OR(JI8>0,JJ8>0,JK8>0),"x",""),"") -> x | HQ8: n/a | HS8: x | HU8: x | HX8: x | HZ8: x | IA8: m | IC8: x | ID8: 19/20 | IE8: x | IF8: x | IG8: x | IH8: x | II8: x | IJ8: x | IK8: x | IL8: x | IN8: 12 | IQ8: 12 | JA8: =COUNTIF(IO8:IZ8,">=0.0") -> 1 | JC8: 8.5 | JF8: 7.3 | JJ8: m | JP8: =COUNTIF(JD8:JO8,">=0.0") -> 1 | LN8: =IFERROR(ROWS($IL$8:IL8)," ") -> 1 | LO8: =IFERROR(IF([1]Checklist!$C$3='GenInfo (2)'!E8,'GenInfo (2)'!LN8," ")," ") -> 1 | LP8: =IFERROR(SMALL($LO$8:$LO$94,ROWS($IL$8:IL8))," ") -> 1 | LQ8: =IFERROR(ROWS($IL$8:IL8)," ") -> 1 | LR8: =IFERROR(IF([1]Checklist!$C$4='GenInfo (2)'!E8,'GenInfo (2)'!LQ8," ")," ") | LS8: =IFERROR(SMALL($LR$8:$LR$94,ROWS($IL$8:IL8))," ") -> 5 | LT8: =IFERROR(ROWS($IL$8:IL8)," ") -> 1 | LU8: =IFERROR(IF([1]Checklist!$C$5='GenInfo (2)'!E8,'GenInfo (2)'!LT8," ")," ") | LV8: =IFERROR(SMALL($LU$8:$LU$94,ROWS($IL$8:IL8))," ") -> 8 | LW8: =IFERROR(ROWS($IL$8:IL8)," ") -> 1 | LX8: =IFERROR(IF([1]Checklist!$C$6='GenInfo (2)'!E8,'GenInfo (2)'!LW8," ")," ") | LY8: =IFERROR(SMALL($LX$8:$LX$94,ROWS($IL$8:IL8))," ") -> 10 | LZ8: =IFERROR(ROWS($IL$8:IL8)," ") -> 1 | MA8: =IFERROR(IF([1]Checklist!$C$7='GenInfo (2)'!E8,'GenInfo (2)'!LZ8," ")," ") | MB8: =IFERROR(SMALL($MA$8:$MA$94,ROWS($IL$8:IL8))," ") -> 13 | MC8: =IFERROR(ROWS($IL$8:IL8)," ") -> 1 | MD8: =IFERROR(IF([1]Checklist!$C$8='GenInfo (2)'!E8,'GenInfo (2)'!MC8," ")," ") | ME8: =IFERROR(SMALL($MD$8:$MD$94,ROWS($IL$8:IL8))," ") -> 17 | MF8: =IFERROR(ROWS($IL$8:IL8)," ") -> 1 | MG8: =IFERROR(IF([1]Checklist!$C$9='GenInfo (2)'!E8,'GenInfo (2)'!MF8," ")," ") | MH8: =IFERROR(SMALL($MG$8:$MG$94,ROWS($IL$8:IL8))," ") -> 18 | MI8: =IFERROR(ROWS($IL$8:$IL8)," ") -> 1 | MJ8: =IFERROR(IF([1]Checklist!$C$10='GenInfo (2)'!E8,'GenInfo (2)'!MI8," ")," ") | MK8: =IFERROR(SMALL($MJ$8:$MJ$94,ROWS($IL$8:IL8))," ") -> 21 | ML8: =IFERROR(ROWS($IL$8:IL8)," ") -> 1 | MM8: =IFERROR(IF([1]Checklist!$C$11='GenInfo (2)'!E8,'GenInfo (2)'!ML8," ")," ") | MN8: =IFERROR(SMALL($MM$8:$MM$94,ROWS($IL$8:IL8))," ") -> 23 | MO8: =IFERROR(ROWS($IL$8:IL8)," ") -> 1 | MP8: =IFERROR(IF([1]Checklist!$C$12='GenInfo (2)'!E8,'GenInfo (2)'!MO8," ")," ") | MQ8: =IFERROR(SMALL($MP$8:$MP$94,ROWS($IL$8:IL8))," ") -> 26 | MR8: =IFERROR(ROWS($IL$8:IL8)," ") -> 1 | MS8: =IFERROR(IF([1]Checklist!$C$13='GenInfo (2)'!E8,'GenInfo (2)'!MR8," ")," ") | MT8: =IFERROR(SMALL($MS$8:$MS$94,ROWS($IL$8:IL8))," ") -> 27 | MU8: =IFERROR(ROWS($IL$8:IL8)," ") -> 1 | MV8: =IFERROR(IF([1]Checklist!$C$14='GenInfo (2)'!E8,'GenInfo (2)'!MU8," ")," ") | MW8: =IFERROR(SMALL($MV$8:$MV$94,ROWS($IL$8:IL8))," ") -> 31 | MX8: =IFERROR(ROWS($IL$8:IL8)," ") -> 1 | MY8: =IFERROR(IF([1]Checklist!$C$15='GenInfo (2)'!E8,'GenInfo (2)'!MX8," ")," ") | MZ8: =IFERROR(SMALL($MY$8:$MY$94,ROWS($IL$8:IL8))," ") -> 34 | NA8: =IFERROR(ROWS($IL$8:IL8)," ") -> 1 | NB8: =IFERROR(IF([1]Checklist!$C$16='GenInfo (2)'!E8,'GenInfo (2)'!NA8," ")," ") | NC8: =IFERROR(SMALL($NB$8:$NB$94,ROWS($IL$8:IL8))," ") -> 42 | ND8: =IFERROR(ROWS($IL$8:IL8)," ") -> 1 | NE8: =IFERROR(IF([1]Checklist!$C$17='GenInfo (2)'!E8,'GenInfo (2)'!ND8," ")," ") | NF8: =IFERROR(SMALL($NE$8:$NE$94,ROWS($IL$8:IL8))," ") -> 46
A9: x | B9: 14 | C9: Sample02 | D9: Student02 | E9: Antonia Pantoja Hs | F9: N7996585 | G9: Enrolled | I9: SSample02@asn.com | J9: 773-555-0002 | V9: 43159 | W9: Current | AB9: Jamie Myers | AC9: (708) 738-1497 | AD9: jamie_myers@lcfs.org | AE9: Luthern Child & Family Services | AF9: 7601 S. Kostner | AH9: Chicago | AI9: IL | AJ9: 60652 | AL9: =IFERROR(DATEDIF(AN9,V9,"y"),"") -> 18 | AM9: =IFERROR(DATEDIF($AN9,TODAY(),"y"),"") -> 22 | AN9: 36493 | AO9: =IFERROR(DATEDIF(TODAY(),EDATE(AN9,(12*21)),"m"),"") | AP9: F | AQ9: Caucasian | AR9: Foster home | AS9: 1 | AU9: 16 | AV9: 2 | AW9: 730 | AX9: Junior | AY9: No | AZ9: No | BA9: Pregnant | BE9: =IFERROR(COUNTIF(CI9,">0")+COUNTIF(CS9,">0")+COUNTIF(DC9,">0")+COUNTIF(DM9,">0")+COUNTIF(DW9,">0")+COUNTIF(EG9,">0")," ") -> 6 | BF9: =IFERROR(COUNTIF(CJ9,">0")+COUNTIF(CT9,">0")+COUNTIF(DD9,">0")+COUNTIF(DN9,">0")+COUNTIF(DX9,">0")+COUNTIF(EH9,">0")," ") -> 4 | BG9: =IFERROR(COUNTIF(CK9,"<49.5%")+COUNTIF(CU9,"<49.5%")+COUNTIF(DE9,"<49.5%")+COUNTIF(DO9,"<49.5%")+COUNTIF(DY9,"<49.5%")+COUNTIF(EI9,"<49.5%")," ") -> 4 | BH9: =IFERROR(AVERAGE(CK9,CU9,DE9,DO9,DY9,EI9)," ") -> 0.35534188 | BI9: =IFERROR(BG9/BE9," ") -> 0.66666667 | BJ9: =IFERROR(COUNTIF(CN9,">0")+COUNTIF(CW9,">0")+COUNTIF(DH9,">0")+COUNTIF(DR9,">0")+COUNTIF(EB9,">0")+COUNTIF(EL9,">0")," ") -> 3 | BK9: =IFERROR(BJ9/BE9," ") -> 0.5 | BL9: =IFERROR(SUM(BV9,CD9,CN9,CW9,DH9,DR9,EB9,EL9),"") -> 8 | BM9: =IFERROR(SUM(BW9,CE9,CO9,CX9,DI9,DS9,EC9,EM9),"") -> 41 | BQ9: 18 | BR9: 9 | BS9: =IFERROR(BR9/BQ9," ") -> 0.5 | BT9: 0 | BU9: 0 | BV9: 0 | BW9: 0 | CA9: 7 | CB9: 5 | CC9: =IFERROR(CB9/CA9," ") -> 0.71428571 | CD9: 0 | CE9: 0 | CI9: 13 | CJ9: 8 | CK9: =IFERROR(CJ9/CI9," ") -> 0.61538462 | CL9: 0 | CM9: 0 | CN9: 0 | CO9: 0 | CS9: 4 | CT9: 4 | CU9: =IFERROR(CT9/CS9," ") -> 1 | CV9: 3 | CW9: 2 | CX9: 5 | CY9: 30 | DC9: 15 | DD9: 4 | DE9: =IFERROR(DD9/DC9," ") -> 0.26666667 | DF9: 2 | DG9: 2 | DH9: 4 | DI9: 24 | DM9: 8 | DN9: 2 | DO9: =IFERROR(DN9/DM9," ") -> 0.25 | DP9: 2 | DQ9: 0 | DR9: 2 | DS9: 12 | DW9: 18 | DX9: 0 | DY9: =IFERROR(DX9/DW9," ") -> 0 | DZ9: 0 | EA9: 0 | EB9: 0 | EC9: 0 | EG9: 18 | EH9: 0 | EI9: =IFERROR(EH9/EG9," ") -> 0 | EJ9: 0 | EK9: 0 | EL9: 0 | EM9: 0 | ES9: =IFERROR(ER9/EQ9," ") | ET9: 0 | EV9: 0 | EW9: 0 | FC9: =IFERROR(FB9/FA9," ") | FH9: =SUM(FD9:FG9) -> 0 | FN9: =IFERROR(FM9/FL9," ") | FS9: =SUM(FO9:FR9) -> 0 | FY9: =IFERROR(FX9/FW9," ") | GD9: =SUM(FZ9:GC9) -> 0 | GF9: 12.5 | GG9: Senior | GI9: 0.25 | GK9: =IFERROR(SUM(GH9:GJ9)," ") -> 0.25 | GL9: 0 | GN9: =IFERROR(SUM(GL9:GM9)," ") -> 0 | GO9: =IFERROR(GF9+GK9+GN9," ") -> 12.75 | GQ9: x | GR9: x | GS9: x | GT9: x | GU9: x | GV9: x | GW9: x | GX9: no | GY9: =IFERROR(IF(IN9>0,"X",""),"") -> X | GZ9: =IFERROR(IF(JC9>0,"X",""),"") -> X | HA9: x | HB9: x | HC9: 0 | HD9: 0 | HE9: 0 | HF9: 0 | HG9: x | HH9: 0 | HI9: 0 | HJ9: 0 | HK9: 0 | HL9: =IFERROR(IF(OR(IQ9>0,IR9>0,IS9>0),"x",""),"") -> x | HM9: =IFERROR(IF(OR(IT9>0,IU9>0,IV9>0),"x",""),"") | HN9: n/a | HO9: =IFERROR(IF(OR(JE9>0,JF9>0,JG9>0,JH9>0),"x",""),"") -> x | HP9: =IFERROR(IF(OR(JI9>0,JJ9>0,JK9>0),"x",""),"") -> x | HQ9: n/a | HS9: x | HX9: x | HZ9: x | IA9: m | IC9: x | ID9: 19/20 | IE9: x | IF9: x | IG9: x | IH9: x | II9: x | IJ9: x | IK9: x | IN9: 5.3 | IQ9: 6 | JA9: =COUNTIF(IO9:IZ9,">=0.0") -> 1 | JC9: 5.9 | JF9: 5.5 | JJ9: m | JP9: =COUNTIF(JD9:JO9,">=0.0") -> 1 | LN9: =IFERROR(ROWS($IL$8:IL9)," ") -> 2 | LO9: =IFERROR(IF([1]Checklist!$C$3='GenInfo (2)'!E9,'GenInfo (2)'!LN9," ")," ") -> 2 | LP9: =IFERROR(SMALL($LO$8:$LO$94,ROWS($IL$8:IL9))," ") -> 2 | LQ9: =IFERROR(ROWS($IL$8:IL9)," ") -> 2 | LR9: =IFERROR(IF([1]Checklist!$C$4='GenInfo (2)'!E9,'GenInfo (2)'!LQ9," ")," ") | LS9: =IFERROR(SMALL($LR$8:$LR$94,ROWS($IL$8:IL9))," ") -> 6 | LT9: =IFERROR(ROWS($IL$8:IL9)," ") -> 2 | LU9: =IFERROR(IF([1]Checklist!$C$5='GenInfo (2)'!E9,'GenInfo (2)'!LT9," ")," ") | LV9: =IFERROR(SMALL($LU$8:$LU$94,ROWS($IL$8:IL9))," ") -> 9 | LW9: =IFERROR(ROWS($IL$8:IL9)," ") -> 2 | LX9: =IFERROR(IF([1]Checklist!$C$6='GenInfo (2)'!E9,'GenInfo (2)'!LW9," ")," ") | LY9: =IFERROR(SMALL($LX$8:$LX$94,ROWS($IL$8:IL9))," ") -> 11 | LZ9: =IFERROR(ROWS($IL$8:IL9)," ") -> 2 | MA9: =IFERROR(IF([1]Checklist!$C$7='GenInfo (2)'!E9,'GenInfo (2)'!LZ9," ")," ") | MB9: =IFERROR(SMALL($MA$8:$MA$94,ROWS($IL$8:IL9))," ") -> 14 | MC9: =IFERROR(ROWS($IL$8:IL9)," ") -> 2 | MD9: =IFERROR(IF([1]Checklist!$C$8='GenInfo (2)'!E9,'GenInfo (2)'!MC9," ")," ") | ME9: =IFERROR(SMALL($MD$8:$MD$94,ROWS($IL$8:IL9))," ") | MF9: =IFERROR(ROWS($IL$8:IL9)," ") -> 2 | MG9: =IFERROR(IF([1]Checklist!$C$9='GenInfo (2)'!E9,'GenInfo (2)'!MF9," ")," ") | MH9: =IFERROR(SMALL($MG$8:$MG$94,ROWS($IL$8:IL9))," ") -> 19 | MI9: =IFERROR(ROWS($IL$8:$IL9)," ") -> 2 | MJ9: =IFERROR(IF([1]Checklist!$C$10='GenInfo (2)'!E9,'GenInfo (2)'!MI9," ")," ") | MK9: =IFERROR(SMALL($MJ$8:$MJ$94,ROWS($IL$8:IL9))," ") -> 22 | ML9: =IFERROR(ROWS($IL$8:IL9)," ") -> 2 | MM9: =IFERROR(IF([1]Checklist!$C$11='GenInfo (2)'!E9,'GenInfo (2)'!ML9," ")," ") | MN9: =IFERROR(SMALL($MM$8:$MM$94,ROWS($IL$8:IL9))," ") -> 24 | MO9: =IFERROR(ROWS($IL$8:IL9)," ") -> 2 | MP9: =IFERROR(IF([1]Checklist!$C$12='GenInfo (2)'!E9,'GenInfo (2)'!MO9," ")," ") | MQ9: =IFERROR(SMALL($MP$8:$MP$94,ROWS($IL$8:IL9))," ") | MR9: =IFERROR(ROWS($IL$8:IL9)," ") -> 2 | MS9: =IFERROR(IF([1]Checklist!$C$13='GenInfo (2)'!E9,'GenInfo (2)'!MR9," ")," ") | MT9: =IFERROR(SMALL($MS$8:$MS$94,ROWS($IL$8:IL9))," ") -> 28 | MU9: =IFERROR(ROWS($IL$8:IL9)," ") -> 2 | MV9: =IFERROR(IF([1]Checklist!$C$14='GenInfo (2)'!E9,'GenInfo (2)'!MU9," ")," ") | MW9: =IFERROR(SMALL($MV$8:$MV$94,ROWS($IL$8:IL9))," ") -> 32 | MX9: =IFERROR(ROWS($IL$8:IL9)," ") -> 2 | MY9: =IFERROR(IF([1]Checklist!$C$15='GenInfo (2)'!E9,'GenInfo (2)'!MX9," ")," ") | MZ9: =IFERROR(SMALL($MY$8:$MY$94,ROWS($IL$8:IL9))," ") -> 35 | NA9: =IFERROR(ROWS($IL$8:IL9)," ") -> 2 | NB9: =IFERROR(IF([1]Checklist!$C$16='GenInfo (2)'!E9,'GenInfo (2)'!NA9," ")," ") | NC9: =IFERROR(SMALL($NB$8:$NB$94,ROWS($IL$8:IL9))," ") -> 43 | ND9: =IFERROR(ROWS($IL$8:IL9)," ") -> 2 | NE9: =IFERROR(IF([1]Checklist!$C$17='GenInfo (2)'!E9,'GenInfo (2)'!ND9," ")," ") | NF9: =IFERROR(SMALL($NE$8:$NE$94,ROWS($IL$8:IL9))," ") -> 47
A10: x | B10: 19 | C10: Sample03 | D10: Student03 | E10: Antonia Pantoja Hs | F10: Y5686785 | G10: Enrolled | I10: SSample03@asn.com | J10: 773-555-0003 | L10: 43948 | M10: 43949 | O10: 43922 | V10: 43951 | W10: Current | AB10: Trella Wade-Mitchell | AC10: (708) 718-6204 | AD10: twademitchell@nyap.org | AE10: NYAP | AM10: 17 | AN10: 37618 | AP10: F | AQ10: African American | AR10: Foster home | AS10: 0 | AT10: Unk | AU10: 14 | AV10: 4 | AW10: Unk | AX10: Pendinng | AY10: Unk | AZ10: No | BA10: No | GK10: =IFERROR(SUM(GH10:GJ10)," ") -> 0 | GQ10: x | GR10: x | GT10: x | GU10: x | GW10: x | GX10: x | GY10: x | GZ10: x | HA10: x | HG10: x | HN10: n/a | HQ10: n/a | IC10: x | IL10: x | JP10: =COUNTIF(JD10:JO10,">=0.0") -> 0 | LN10: =IFERROR(ROWS($IL$8:IL10)," ") -> 3 | LO10: =IFERROR(IF([1]Checklist!$C$3='GenInfo (2)'!E10,'GenInfo (2)'!LN10," ")," ") -> 3 | LP10: =IFERROR(SMALL($LO$8:$LO$94,ROWS($IL$8:IL10))," ") -> 3 | LQ10: =IFERROR(ROWS($IL$8:IL10)," ") -> 3 | LR10: =IFERROR(IF([1]Checklist!$C$4='GenInfo (2)'!E10,'GenInfo (2)'!LQ10," ")," ") | LS10: =IFERROR(SMALL($LR$8:$LR$94,ROWS($IL$8:IL10))," ") -> 7 | LT10: =IFERROR(ROWS($IL$8:IL10)," ") -> 3 | LU10: =IFERROR(IF([1]Checklist!$C$5='GenInfo (2)'!E10,'GenInfo (2)'!LT10," ")," ") | LV10: =IFERROR(SMALL($LU$8:$LU$94,ROWS($IL$8:IL10))," ") | LW10: =IFERROR(ROWS($IL$8:IL10)," ") -> 3 | LX10: =IFERROR(IF([1]Checklist!$C$6='GenInfo (2)'!E10,'GenInfo (2)'!LW10," ")," ") | LY10: =IFERROR(SMALL($LX$8:$LX$94,ROWS($IL$8:IL10))," ") -> 12 | LZ10: =IFERROR(ROWS($IL$8:IL10)," ") -> 3 | MA10: =IFERROR(IF([1]Checklist!$C$7='GenInfo (2)'!E10,'GenInfo (2)'!LZ10," ")," ") | MB10: =IFERROR(SMALL($MA$8:$MA$94,ROWS($IL$8:IL10))," ") -> 15 | MC10: =IFERROR(ROWS($IL$8:IL10)," ") -> 3 | MD10: =IFERROR(IF([1]Checklist!$C$8='GenInfo (2)'!E10,'GenInfo (2)'!MC10," ")," ") | ME10: =IFERROR(SMALL($MD$8:$MD$94,ROWS($IL$8:IL10))," ") | MF10: =IFERROR(ROWS($IL$8:IL10)," ") -> 3 | MG10: =IFERROR(IF([1]Checklist!$C$9='GenInfo (2)'!E10,'GenInfo (2)'!MF10," ")," ") | MH10: =IFERROR(SMALL($MG$8:$MG$94,ROWS($IL$8:IL10))," ") -> 20 | MI10: =IFERROR(ROWS($IL$8:$IL10)," ") -> 3 | MJ10: =IFERROR(IF([1]Checklist!$C$10='GenInfo (2)'!E10,'GenInfo (2)'!MI10," ")," ") | MK10: =IFERROR(SMALL($MJ$8:$MJ$94,ROWS($IL$8:IL10))," ") | ML10: =IFERROR(ROWS($IL$8:IL10)," ") -> 3 | MM10: =IFERROR(IF([1]Checklist!$C$11='GenInfo (2)'!E10,'GenInfo (2)'!ML10," ")," ") | MN10: =IFERROR(SMALL($MM$8:$MM$94,ROWS($IL$8:IL10))," ") -> 25 | MO10: =IFERROR(ROWS($IL$8:IL10)," ") -> 3 | MP10: =IFERROR(IF([1]Checklist!$C$12='GenInfo (2)'!E10,'GenInfo (2)'!MO10," ")," ") | MQ10: =IFERROR(SMALL($MP$8:$MP$94,ROWS($IL$8:IL10))," ") | MR10: =IFERROR(ROWS($IL$8:IL10)," ") -> 3 | MS10: =IFERROR(IF([1]Checklist!$C$13='GenInfo (2)'!E10,'GenInfo (2)'!MR10," ")," ") | MT10: =IFERROR(SMALL($MS$8:$MS$94,ROWS($IL$8:IL10))," ") -> 29 | MU10: =IFERROR(ROWS($IL$8:IL10)," ") -> 3 | MV10: =IFERROR(IF([1]Checklist!$C$14='GenInfo (2)'!E10,'GenInfo (2)'!MU10," ")," ") | MW10: =IFERROR(SMALL($MV$8:$MV$94,ROWS($IL$8:IL10))," ") -> 33 | MX10: =IFERROR(ROWS($IL$8:IL10)," ") -> 3 | MY10: =IFERROR(IF([1]Checklist!$C$15='GenInfo (2)'!E10,'GenInfo (2)'!MX10," ")," ") | MZ10: =IFERROR(SMALL($MY$8:$MY$94,ROWS($IL$8:IL10))," ") -> 36 | NA10: =IFERROR(ROWS($IL$8:IL10)," ") -> 3 | NB10: =IFERROR(IF([1]Checklist!$C$16='GenInfo (2)'!E10,'GenInfo (2)'!NA10," ")," ") | NC10: =IFERROR(SMALL($NB$8:$NB$94,ROWS($IL$8:IL10))," ") -> 44 | ND10: =IFERROR(ROWS($IL$8:IL10)," ") -> 3 | NE10: =IFERROR(IF([1]Checklist!$C$17='GenInfo (2)'!E10,'GenInfo (2)'!ND10," ")," ") | NF10: =IFERROR(SMALL($NE$8:$NE$94,ROWS($IL$8:IL10))," ") -> 48
A11: x | B11: 20 | C11: Sample03 | D11: Student03 | E11: Antonia Pantoja Hs | F11: Y5686785 | G11: Referral not accepted by school | I11: SSample03@asn.com | J11: 773-555-0003 | L11: 43804 | M11: 43804 | N11: x | O11: Dec-20 EXT | R11: Not accepted | S11: 43874 | AB11: Darnise Horne | AC11: 708-747-2655 | AD11: dahorne@nyap.org | AE11: NYAP | AF11: 4747 Lincoln Mall Dr. | AG11: Suite 101 | AH11: Matteson | AI11: IL | AJ11: 60443 | AL11: =IFERROR(DATEDIF(AN11,V11,"y"),"") | AM11: =IFERROR(DATEDIF($AN11,TODAY(),"y"),"") -> 19 | AN11: 37618 | AO11: =IFERROR(DATEDIF(TODAY(),EDATE(AN11,(12*21)),"m"),"") -> 23 | AP11: F | AQ11: African American | AR11: Home of relative | AS11: 0 | AT11: 240 | AU11: 14 | AV11: 3 | AW11: 30 | AX11: Freshman | AY11: Unk | AZ11: No | BA11: No | BE11: =IFERROR(COUNTIF(CI11,">0")+COUNTIF(CS11,">0")+COUNTIF(DC11,">0")+COUNTIF(DM11,">0")+COUNTIF(DW11,">0")+COUNTIF(EG11,">0")," ") -> 0 | BF11: =IFERROR(COUNTIF(CJ11,">0")+COUNTIF(CT11,">0")+COUNTIF(DD11,">0")+COUNTIF(DN11,">0")+COUNTIF(DX11,">0")+COUNTIF(EH11,">0")," ") -> 0 | BG11: =IFERROR(COUNTIF(CK11,"<49.5%")+COUNTIF(CU11,"<49.5%")+COUNTIF(DE11,"<49.5%")+COUNTIF(DO11,"<49.5%")+COUNTIF(DY11,"<49.5%")+COUNTIF(EI11,"<49.5%")," ") -> 0 | BH11: =IFERROR(AVERAGE(CK11,CU11,DE11,DO11,DY11,EI11)," ") | BI11: =IFERROR(BG11/BE11," ") | BJ11: =IFERROR(COUNTIF(CN11,">0")+COUNTIF(CW11,">0")+COUNTIF(DH11,">0")+COUNTIF(DR11,">0")+COUNTIF(EB11,">0")+COUNTIF(EL11,">0")," ") -> 0 | BK11: =IFERROR(BJ11/BE11," ") | BL11: =IFERROR(SUM(BV11,CD11,CN11,CW11,DH11,DR11,EB11,EL11),"") -> 0 | BM11: =IFERROR(SUM(BW11,CE11,CO11,CX11,DI11,DS11,EC11,EM11),"") -> 0 | BS11: =IFERROR(BR11/BQ11," ") | BT11: 0 | BU11: 0 | BV11: 0 | BW11: 0 | CC11: =IFERROR(CB11/CA11," ") | CD11: 0 | CE11: 0 | CK11: =IFERROR(CJ11/CI11," ") | CL11: 0 | CM11: 0 | CN11: 0 | CO11: 0 | CU11: =IFERROR(CT11/CS11," ") | CV11: 0 | CW11: 0 | CX11: 0 | CY11: 0 | DE11: =IFERROR(DD11/DC11," ") | DF11: 0 | DG11: 0 | DH11: 0 | DI11: 0 | DO11: =IFERROR(DN11/DM11," ") | DP11: 0 | DQ11: 0 | DR11: 0 | DS11: 0 | DY11: =IFERROR(DX11/DW11," ") | DZ11: 0 | EA11: 0 | EB11: 0 | EC11: 0 | EI11: =IFERROR(EH11/EG11," ") | EJ11: 0 | EK11: 0 | EL11: 0 | EM11: 0 | ES11: =IFERROR(ER11/EQ11," ") | ET11: 0 | EV11: 0 | EW11: 0 | FC11: =IFERROR(FB11/FA11," ") | FH11: =SUM(FD11:FG11) -> 0 | FN11: =IFERROR(FM11/FL11," ") | FS11: =SUM(FO11:FR11) -> 0 | FY11: =IFERROR(FX11/FW11," ") | GD11: =SUM(FZ11:GC11) -> 0 | GK11: =IFERROR(SUM(GH11:GJ11)," ") -> 0 | GN11: =IFERROR(SUM(GL11:GM11)," ") -> 0 | GO11: =IFERROR(GF11+GK11+GN11," ") | GQ11: x | GS11: x | GY11: =IFERROR(IF(IN11>0,"X",""),"") | GZ11: =IFERROR(IF(JC11>0,"X",""),"") | HL11: =IFERROR(IF(OR(IQ11>0,IR11>0,IS11>0),"x",""),"") | HM11: =IFERROR(IF(OR(IT11>0,IU11>0,IV11>0),"x",""),"") | HN11: =IFERROR(IF(OR(IW11>0,IX11>0,IY11>0,IZ11>0),"x",""),"") | HO11: =IFERROR(IF(OR(JE11>0,JF11>0,JG11>0,JH11>0),"x",""),"") | HP11: =IFERROR(IF(OR(JI11>0,JJ11>0,JK11>0),"x",""),"") | HQ11: =IFERROR(IF(OR(JL11>0,JM11>0,JN11>0,JO11>0),"x",""),"") | JA11: =COUNTIF(IO11:IZ11,">=0.0") -> 0 | JP11: =COUNTIF(JD11:JO11,">=0.0") -> 0 | LN11: =IFERROR(ROWS($IL$8:IL11)," ") -> 4 | LO11: =IFERROR(IF([1]Checklist!$C$3='GenInfo (2)'!E11,'GenInfo (2)'!LN11," ")," ") -> 4 | LP11: =IFERROR(SMALL($LO$8:$LO$94,ROWS($IL$8:IL11))," ") -> 4 | LQ11: =IFERROR(ROWS($IL$8:IL11)," ") -> 4 | LR11: =IFERROR(IF([1]Checklist!$C$4='GenInfo (2)'!E11,'GenInfo (2)'!LQ11," ")," ") | LS11: =IFERROR(SMALL($LR$8:$LR$94,ROWS($IL$8:IL11))," ") | LT11: =IFERROR(ROWS($IL$8:IL11)," ") -> 4 | LU11: =IFERROR(IF([1]Checklist!$C$5='GenInfo (2)'!E11,'GenInfo (2)'!LT11," ")," ") | LV11: =IFERROR(SMALL($LU$8:$LU$94,ROWS($IL$8:IL11))," ") | LW11: =IFERROR(ROWS($IL$8:IL11)," ") -> 4 | LX11: =IFERROR(IF([1]Checklist!$C$6='GenInfo (2)'!E11,'GenInfo (2)'!LW11," ")," ") | LY11: =IFERROR(SMALL($LX$8:$LX$94,ROWS($IL$8:IL11))," ") | LZ11: =IFERROR(ROWS($IL$8:IL11)," ") -> 4 | MA11: =IFERROR(IF([1]Checklist!$C$7='GenInfo (2)'!E11,'GenInfo (2)'!LZ11," ")," ") | MB11: =IFERROR(SMALL($MA$8:$MA$94,ROWS($IL$8:IL11))," ") -> 16 | MC11: =IFERROR(ROWS($IL$8:IL11)," ") -> 4 | MD11: =IFERROR(IF([1]Checklist!$C$8='GenInfo (2)'!E11,'GenInfo (2)'!MC11," ")," ") | ME11: =IFERROR(SMALL($MD$8:$MD$94,ROWS($IL$8:IL11))," ") | MF11: =IFERROR(ROWS($IL$8:IL11)," ") -> 4 | MG11: =IFERROR(IF([1]Checklist!$C$9='GenInfo (2)'!E11,'GenInfo (2)'!MF11," ")," ") | MH11: =IFERROR(SMALL($MG$8:$MG$94,ROWS($IL$8:IL11))," ") | MI11: =IFERROR(ROWS($IL$8:$IL11)," ") -> 4 | MJ11: =IFERROR(IF([1]Checklist!$C$10='GenInfo (2)'!E11,'GenInfo (2)'!MI11," ")," ") | MK11: =IFERROR(SMALL($MJ$8:$MJ$94,ROWS($IL$8:IL11))," ") | ML11: =IFERROR(ROWS($IL$8:IL11)," ") -> 4 | MM11: =IFERROR(IF([1]Checklist!$C$11='GenInfo (2)'!E11,'GenInfo (2)'!ML11," ")," ") | MN11: =IFERROR(SMALL($MM$8:$MM$94,ROWS($IL$8:IL11))," ") | MO11: =IFERROR(ROWS($IL$8:IL11)," ") -> 4 | MP11: =IFERROR(IF([1]Checklist!$C$12='GenInfo (2)'!E11,'GenInfo (2)'!MO11," ")," ") | MQ11: =IFERROR(SMALL($MP$8:$MP$94,ROWS($IL$8:IL11))," ") | MR11: =IFERROR(ROWS($IL$8:IL11)," ") -> 4 | MS11: =IFERROR(IF([1]Checklist!$C$13='GenInfo (2)'!E11,'GenInfo (2)'!MR11," ")," ") | MT11: =IFERROR(SMALL($MS$8:$MS$94,ROWS($IL$8:IL11))," ") -> 30 | MU11: =IFERROR(ROWS($IL$8:IL11)," ") -> 4 | MV11: =IFERROR(IF([1]Checklist!$C$14='GenInfo (2)'!E11,'GenInfo (2)'!MU11," ")," ") | MW11: =IFERROR(SMALL($MV$8:$MV$94,ROWS($IL$8:IL11))," ") | MX11: =IFERROR(ROWS($IL$8:IL11)," ") -> 4 | MY11: =IFERROR(IF([1]Checklist!$C$15='GenInfo (2)'!E11,'GenInfo (2)'!MX11," ")," ") | MZ11: =IFERROR(SMALL($MY$8:$MY$94,ROWS($IL$8:IL11))," ") -> 37 | NA11: =IFERROR(ROWS($IL$8:IL11)," ") -> 4 | NB11: =IFERROR(IF([1]Checklist!$C$16='GenInfo (2)'!E11,'GenInfo (2)'!NA11," ")," ") | NC11: =IFERROR(SMALL($NB$8:$NB$94,ROWS($IL$8:IL11))," ") -> 45 | ND11: =IFERROR(ROWS($IL$8:IL11)," ") -> 4 | NE11: =IFERROR(IF([1]Checklist!$C$17='GenInfo (2)'!E11,'GenInfo (2)'!ND11," ")," ") | NF11: =IFERROR(SMALL($NE$8:$NE$94,ROWS($IL$8:IL11))," ") -> 49
A12: x | B12: 27 | C12: Sample04 | D12: Student04 | E12: Asn Preparatory Institute | F12: T6798567 | G12: Enrolled | I12: SSample04@asn.com | J12: 773-555-0004 | V12: 43509 | W12: Current | AB12: Hope King-Stapleton | AC12: (773) 981-0536 | AE12: UCAN | AF12: 13700 S Indiana | AH12: Riverdale | AI12: IL | AJ12: 60827 | AL12: =IFERROR(DATEDIF(AN12,V12,"y"),"") -> 18 | AM12: =IFERROR(DATEDIF($AN12,TODAY(),"y"),"") -> 21 | AN12: 36572 | AO12: =IFERROR(DATEDIF(TODAY(),EDATE(AN12,(12*21)),"m"),"") | AP12: F | AQ12: African American | AR12: TLP | AX12: GED | AY12: No | AZ12: Yes | BA12: Yes | BE12: =IFERROR(COUNTIF(CI12,">0")+COUNTIF(CS12,">0")+COUNTIF(DC12,">0")+COUNTIF(DM12,">0")+COUNTIF(DW12,">0")+COUNTIF(EG12,">0")," ") -> 6 | BF12: =IFERROR(COUNTIF(CJ12,">0")+COUNTIF(CT12,">0")+COUNTIF(DD12,">0")+COUNTIF(DN12,">0")+COUNTIF(DX12,">0")+COUNTIF(EH12,">0")," ") -> 4 | BG12: =IFERROR(COUNTIF(CK12,"<49.5%")+COUNTIF(CU12,"<49.5%")+COUNTIF(DE12,"<49.5%")+COUNTIF(DO12,"<49.5%")+COUNTIF(DY12,"<49.5%")+COUNTIF(EI12,"<49.5%")," ") -> 2 | BH12: =IFERROR(AVERAGE(CK12,CU12,DE12,DO12,DY12,EI12)," ") -> 0.60416667 | BI12: =IFERROR(BG12/BE12," ") -> 0.33333333 | BJ12: =IFERROR(COUNTIF(CN12,">0")+COUNTIF(CW12,">0")+COUNTIF(DH12,">0")+COUNTIF(DR12,">0")+COUNTIF(EB12,">0")+COUNTIF(EL12,">0")," ") -> 4 | BK12: =IFERROR(BJ12/BE12," ") -> 0.66666667 | BL12: =IFERROR(SUM(BV12,CD12,CN12,CW12,DH12,DR12,EB12,EL12),"") -> 48 | BM12: =IFERROR(SUM(BW12,CE12,CO12,CX12,DI12,DS12,EC12,EM12),"") -> 288 | BQ12: 4 | BR12: 3 | BS12: =IFERROR(BR12/BQ12," ") -> 0.75 | BT12: 0 | BU12: 0 | BV12: 0 | BW12: 0 | CA12: 7 | CB12: 1 | CC12: =IFERROR(CB12/CA12," ") -> 0.14285714 | CD12: 0 | CE12: 0 | CI12: 8 | CJ12: 0 | CK12: =IFERROR(CJ12/CI12," ") -> 0 | CL12: 0 | CM12: 0 | CN12: 0 | CO12: 0 | CS12: 13 | CT12: 0 | CU12: =IFERROR(CT12/CS12," ") -> 0 | CV12: 0 | CW12: 0 | CX12: 0 | CY12: 0 | DC12: 3 | DD12: 3 | DE12: =IFERROR(DD12/DC12," ") -> 1 | DF12: 0 | DG12: 6 | DH12: 6 | DI12: 36 | DM12: 8 | DN12: 5 | DO12: =IFERROR(DN12/DM12," ") -> 0.625 | DP12: 3 | DQ12: 2 | DR12: 5 | DS12: 30 | DW12: 12 | DX12: 12 | DY12: =IFERROR(DX12/DW12," ") -> 1 | DZ12: 10 | EA12: 13 | EB12: 23 | EC12: 138 | EG12: 6 | EH12: 6 | EI12: =IFERROR(EH12/EG12," ") -> 1 | EJ12: 12 | EK12: 2 | EL12: 14 | EM12: 84 | EQ12: 9 | ER12: 9 | ES12: =IFERROR(ER12/EQ12," ") -> 1 | ET12: 16 | EV12: 16 | EW12: 96 | FC12: =IFERROR(FB12/FA12," ") | FH12: =SUM(FD12:FG12) -> 0 | FN12: =IFERROR(FM12/FL12," ") | FS12: =SUM(FO12:FR12) -> 0 | FY12: =IFERROR(FX12/FW12," ") | GD12: =SUM(FZ12:GC12) -> 0 | GG12: GED | GK12: =IFERROR(SUM(GH12:GJ12)," ") -> 0 | GN12: =IFERROR(SUM(GL12:GM12)," ") -> 0 | GO12: =IFERROR(GF12+GK12+GN12," ") -> 0 | GQ12: x | GR12: x | GS12: x | GT12: x | GU12: x | GV12: x | GW12: x | GX12: no | GY12: =IFERROR(IF(IN12>0,"X",""),"") -> X | GZ12: =IFERROR(IF(JC12>0,"X",""),"") -> X | HA12: GED | HB12: GED | HG12: x | HH12: 2 | HI12: 0 | HJ12: 0 | HK12: 0 | HL12: =IFERROR(IF(OR(IQ12>0,IR12>0,IS12>0),"x",""),"") -> x | HM12: =IFERROR(IF(OR(IT12>0,IU12>0,IV12>0),"x",""),"") | HN12: n/a | HO12: =IFERROR(IF(OR(JE12>0,JF12>0,JG12>0,JH12>0),"x",""),"") -> x | HP12: =IFERROR(IF(OR(JI12>0,JJ12>0,JK12>0),"x",""),"") | HQ12: n/a | HR12: GED | HS12: GED | HT12: GED | HU12: GED | HV12: GED | HX12: GED | HY12: GED | HZ12: x | IA12: x | IC12: x | ID12: 19/20 | IE12: x | IF12: x | IG12: x | IH12: x | II12: x | IJ12: x | IK12: x | IL12: x | IN12: 9.6 | IS12: 12 | JA12: =COUNTIF(IO12:IZ12,">=0.0") -> 1 | JC12: 9.5 | JH12: 10 | JP12: =COUNTIF(JD12:JO12,">=0.0") -> 1 | LN12: =IFERROR(ROWS($IL$8:IL12)," ") -> 5 | LO12: =IFERROR(IF([1]Checklist!$C$3='GenInfo (2)'!E12,'GenInfo (2)'!LN12," ")," ") | LP12: =IFERROR(SMALL($LO$8:$LO$94,ROWS($IL$8:IL12))," ") | LQ12: =IFERROR(ROWS($IL$8:IL12)," ") -> 5 | LR12: =IFERROR(IF([1]Checklist!$C$4='GenInfo (2)'!E12,'GenInfo (2)'!LQ12," ")," ") -> 5 | LS12: =IFERROR(SMALL($LR$8:$LR$94,ROWS($IL$8:IL12))," ") | LT12: =IFERROR(ROWS($IL$8:IL12)," ") -> 5 | LU12: =IFERROR(IF([1]Checklist!$C$5='GenInfo (2)'!E12,'GenInfo (2)'!LT12," ")," ") | LV12: =IFERROR(SMALL($LU$8:$LU$94,ROWS($IL$8:IL12))," ") | LW12: =IFERROR(ROWS($IL$8:IL12)," ") -> 5 | LX12: =IFERROR(IF([1]Checklist!$C$6='GenInfo (2)'!E12,'GenInfo (2)'!LW12," ")," ") | LY12: =IFERROR(SMALL($LX$8:$LX$94,ROWS($IL$8:IL12))," ") | LZ12: =IFERROR(ROWS($IL$8:IL12)," ") -> 5 | MA12: =IFERROR(IF([1]Checklist!$C$7='GenInfo (2)'!E12,'GenInfo (2)'!LZ12," ")," ") | MB12: =IFERROR(SMALL($MA$8:$MA$94,ROWS($IL$8:IL12))," ") | MC12: =IFERROR(ROWS($IL$8:IL12)," ") -> 5 | MD12: =IFERROR(IF([1]Checklist!$C$8='GenInfo (2)'!E12,'GenInfo (2)'!MC12," ")," ") | ME12: =IFERROR(SMALL($MD$8:$MD$94,ROWS($IL$8:IL12))," ") | MF12: =IFERROR(ROWS($IL$8:IL12)," ") -> 5 | MG12: =IFERROR(IF([1]Checklist!$C$9='GenInfo (2)'!E12,'GenInfo (2)'!MF12," ")," ") | MH12: =IFERROR(SMALL($MG$8:$MG$94,ROWS($IL$8:IL12))," ") | MI12: =IFERROR(ROWS($IL$8:$IL12)," ") -> 5 | MJ12: =IFERROR(IF([1]Checklist!$C$10='GenInfo (2)'!E12,'GenInfo (2)'!MI12," ")," ") | MK12: =IFERROR(SMALL($MJ$8:$MJ$94,ROWS($IL$8:IL12))," ") | ML12: =IFERROR(ROWS($IL$8:IL12)," ") -> 5 | MM12: =IFERROR(IF([1]Checklist!$C$11='GenInfo (2)'!E12,'GenInfo (2)'!ML12," ")," ") | MN12: =IFERROR(SMALL($MM$8:$MM$94,ROWS($IL$8:IL12))," ") | MO12: =IFERROR(ROWS($IL$8:IL12)," ") -> 5 | MP12: =IFERROR(IF([1]Checklist!$C$12='GenInfo (2)'!E12,'GenInfo (2)'!MO12," ")," ") | MQ12: =IFERROR(SMALL($MP$8:$MP$94,ROWS($IL$8:IL12))," ") | MR12: =IFERROR(ROWS($IL$8:IL12)," ") -> 5 | MS12: =IFERROR(IF([1]Checklist!$C$13='GenInfo (2)'!E12,'GenInfo (2)'!MR12," ")," ") | MT12: =IFERROR(SMALL($MS$8:$MS$94,ROWS($IL$8:IL12))," ") | MU12: =IFERROR(ROWS($IL$8:IL12)," ") -> 5 | MV12: =IFERROR(IF([1]Checklist!$C$14='GenInfo (2)'!E12,'GenInfo (2)'!MU12," ")," ") | MW12: =IFERROR(SMALL($MV$8:$MV$94,ROWS($IL$8:IL12))," ") | MX12: =IFERROR(ROWS($IL$8:IL12)," ") -> 5 | MY12: =IFERROR(IF([1]Checklist!$C$15='GenInfo (2)'!E12,'GenInfo (2)'!MX12," ")," ") | MZ12: =IFERROR(SMALL($MY$8:$MY$94,ROWS($IL$8:IL12))," ") -> 38 | NA12: =IFERROR(ROWS($IL$8:IL12)," ") -> 5 | NB12: =IFERROR(IF([1]Checklist!$C$16='GenInfo (2)'!E12,'GenInfo (2)'!NA12," ")," ") | NC12: =IFERROR(SMALL($NB$8:$NB$94,ROWS($IL$8:IL12))," ") | ND12: =IFERROR(ROWS($IL$8:IL12)," ") -> 5 | NE12: =IFERROR(IF([1]Checklist!$C$17='GenInfo (2)'!E12,'GenInfo (2)'!ND12," ")," ") | NF12: =IFERROR(SMALL($NE$8:$NE$94,ROWS($IL$8:IL12))," ") -> 50
A13: x | B13: 28 | C13: Sample05 | D13: Student05 | E13: Asn Preparatory Institute | F13: U6678589 | G13: Discharged | I13: SSample05@asn.com | J13: 773-555-0005 | L13: 43732 | M13: 43781 | N13: x | O13: 43770 | P13: 43781 | R13: Accepted | V13: 43796 | W13: 43866 | X13: Emancipated | AB13: Paula Grrison | AC13: (708) 668-0760 | AD13: paula.garrison@thresholds.org | AE13: Thresholds Mother's Project | AF13: 1110 W Belmont | AH13: Chicago | AI13: IL | AJ13: 60657 | AL13: =IFERROR(DATEDIF(AN13,V13,"y"),"") -> 20 | AM13: =IFERROR(DATEDIF($AN13,TODAY(),"y"),"") -> 23 | AN13: 36159 | AO13: =IFERROR(DATEDIF(TODAY(),EDATE(AN13,(12*21)),"m"),"") | AP13: F | AQ13: African American | AR13: TLP | AS13: Unk | AT13: Unk | AU13: 3 | AV13: 5 | AW13: 548 | AX13: GED | AY13: Yes | AZ13: Yes | BA13: Yes | BC13: 1 | BE13: =IFERROR(COUNTIF(CI13,">0")+COUNTIF(CS13,">0")+COUNTIF(DC13,">0")+COUNTIF(DM13,">0")+COUNTIF(DW13,">0")+COUNTIF(EG13,">0")," ") -> 2 | BF13: =IFERROR(COUNTIF(CJ13,">0")+COUNTIF(CT13,">0")+COUNTIF(DD13,">0")+COUNTIF(DN13,">0")+COUNTIF(DX13,">0")+COUNTIF(EH13,">0")," ") -> 1 | BG13: =IFERROR(COUNTIF(CK13,"<49.5%")+COUNTIF(CU13,"<49.5%")+COUNTIF(DE13,"<49.5%")+COUNTIF(DO13,"<49.5%")+COUNTIF(DY13,"<49.5%")+COUNTIF(EI13,"<49.5%")," ") -> 1 | BH13: =IFERROR(AVERAGE(CK13,CU13,DE13,DO13,DY13,EI13)," ") -> 0.5 | BI13: =IFERROR(BG13/BE13," ") -> 0.5 | BJ13: =IFERROR(COUNTIF(CN13,">0")+COUNTIF(CW13,">0")+COUNTIF(DH13,">0")+COUNTIF(DR13,">0")+COUNTIF(EB13,">0")+COUNTIF(EL13,">0")," ") -> 0 | BK13: =IFERROR(BJ13/BE13," ") -> 0 | BL13: =IFERROR(SUM(BV13,CD13,CN13,CW13,DH13,DR13,EB13,EL13),"") -> 0 | BM13: =IFERROR(SUM(BW13,CE13,CO13,CX13,DI13,DS13,EC13,EM13),"") -> 0 | BS13: =IFERROR(BR13/BQ13," ") | BT13: 0 | BU13: 0 | BV13: 0 | BW13: 0 | CC13: =IFERROR(CB13/CA13," ") | CD13: 0 | CE13: 0 | CK13: =IFERROR(CJ13/CI13," ") | CL13: 0 | CM13: 0 | CN13: 0 | CO13: 0 | CU13: =IFERROR(CT13/CS13," ") | CV13: 0 | CW13: 0 | CX13: 0 | CY13: 0 | DC13: 2 | DD13: 2 | DE13: =IFERROR(DD13/DC13," ") -> 1 | DF13: 0 | DG13: 0 | DH13: 0 | DI13: 0 | DO13: =IFERROR(DN13/DM13," ") | DP13: 0 | DQ13: 0 | DR13: 0 | DS13: 0 | DW13: 8 | DX13: 0 | DY13: =IFERROR(DX13/DW13," ") -> 0 | DZ13: 0 | EA13: 0 | EB13: 0 | EC13: 0 | EI13: =IFERROR(EH13/EG13," ") | EJ13: 0 | EK13: 0 | EL13: 0 | EM13: 0 | ES13: =IFERROR(ER13/EQ13," ") | ET13: 0 | EV13: 0 | EW13: 0 | FC13: =IFERROR(FB13/FA13," ") | FH13: =SUM(FD13:FG13) -> 0 | FN13: =IFERROR(FM13/FL13," ") | FS13: =SUM(FO13:FR13) -> 0 | FY13: =IFERROR(FX13/FW13," ") | GD13: =SUM(FZ13:GC13) -> 0 | GG13: GED | GK13: =IFERROR(SUM(GH13:GJ13)," ") -> 0 | GN13: =IFERROR(SUM(GL13:GM13)," ") -> 0 | GO13: =IFERROR(GF13+GK13+GN13," ") | GQ13: x | GR13: x | GS13: x | GT13: x | GU13: x | GV13: x | GW13: x | GX13: x | GY13: =IFERROR(IF(IN13>0,"X",""),"") -> X | GZ13: =IFERROR(IF(JC13>0,"X",""),"") -> X | HA13: GED | HB13: GED | HC13: x | HD13: x | HE13: m | HF13: m | HG13: x | HL13: n/a | HM13: =IFERROR(IF(OR(IT13>0,IU13>0,IV13>0),"x",""),"") -> x | HN13: =IFERROR(IF(OR(IW13>0,IX13>0,IY13>0,IZ13>0),"x",""),"") | HO13: n/a | HP13: =IFERROR(IF(OR(JI13>0,JJ13>0,JK13>0),"x",""),"") -> x | HQ13: =IFERROR(IF(OR(JL13>0,JM13>0,JN13>0,JO13>0),"x",""),"") | HR13: GED | HS13: GED | HT13: GED | HU13: GED | HV13: GED | HX13: GED | HY13: GED | IC13: x | IN13: 4.2 | IT13: 4.2 | JA13: =COUNTIF(IO13:IZ13,">=0.0") -> 1 | JC13: 7.6 | JI13: 7.6 | JP13: =COUNTIF(JD13:JO13,">=0.0") -> 1 | LN13: =IFERROR(ROWS($IL$8:IL13)," ") -> 6 | LO13: =IFERROR(IF([1]Checklist!$C$3='GenInfo (2)'!E13,'GenInfo (2)'!LN13," ")," ") | LP13: =IFERROR(SMALL($LO$8:$LO$94,ROWS($IL$8:IL13))," ") | LQ13: =IFERROR(ROWS($IL$8:IL13)," ") -> 6 | LR13: =IFERROR(IF([1]Checklist!$C$4='GenInfo (2)'!E13,'GenInfo (2)'!LQ13," ")," ") -> 6 | LS13: =IFERROR(SMALL($LR$8:$LR$94,ROWS($IL$8:IL13))," ") | LT13: =IFERROR(ROWS($IL$8:IL13)," ") -> 6 | LU13: =IFERROR(IF([1]Checklist!$C$5='GenInfo (2)'!E13,'GenInfo (2)'!LT13," ")," ") | LV13: =IFERROR(SMALL($LU$8:$LU$94,ROWS($IL$8:IL13))," ") | LW13: =IFERROR(ROWS($IL$8:IL13)," ") -> 6 | LX13: =IFERROR(IF([1]Checklist!$C$6='GenInfo (2)'!E13,'GenInfo (2)'!LW13," ")," ") | LY13: =IFERROR(SMALL($LX$8:$LX$94,ROWS($IL$8:IL13))," ") | LZ13: =IFERROR(ROWS($IL$8:IL13)," ") -> 6 | MA13: =IFERROR(IF([1]Checklist!$C$7='GenInfo (2)'!E13,'GenInfo (2)'!LZ13," ")," ") | MB13: =IFERROR(SMALL($MA$8:$MA$94,ROWS($IL$8:IL13))," ") | MC13: =IFERROR(ROWS($IL$8:IL13)," ") -> 6 | MD13: =IFERROR(IF([1]Checklist!$C$8='GenInfo (2)'!E13,'GenInfo (2)'!MC13," ")," ") | ME13: =IFERROR(SMALL($MD$8:$MD$94,ROWS($IL$8:IL13))," ") | MF13: =IFERROR(ROWS($IL$8:IL13)," ") -> 6 | MG13: =IFERROR(IF([1]Checklist!$C$9='GenInfo (2)'!E13,'GenInfo (2)'!MF13," ")," ") | MH13: =IFERROR(SMALL($MG$8:$MG$94,ROWS($IL$8:IL13))," ") | MI13: =IFERROR(ROWS($IL$8:$IL13)," ") -> 6 | MJ13: =IFERROR(IF([1]Checklist!$C$10='GenInfo (2)'!E13,'GenInfo (2)'!MI13," ")," ") | MK13: =IFERROR(SMALL($MJ$8:$MJ$94,ROWS($IL$8:IL13))," ") | ML13: =IFERROR(ROWS($IL$8:IL13)," ") -> 6 | MM13: =IFERROR(IF([1]Checklist!$C$11='GenInfo (2)'!E13,'GenInfo (2)'!ML13," ")," ") | MN13: =IFERROR(SMALL($MM$8:$MM$94,ROWS($IL$8:IL13))," ") | MO13: =IFERROR(ROWS($IL$8:IL13)," ") -> 6 | MP13: =IFERROR(IF([1]Checklist!$C$12='GenInfo (2)'!E13,'GenInfo (2)'!MO13," ")," ") | MQ13: =IFERROR(SMALL($MP$8:$MP$94,ROWS($IL$8:IL13))," ") | MR13: =IFERROR(ROWS($IL$8:IL13)," ") -> 6 | MS13: =IFERROR(IF([1]Checklist!$C$13='GenInfo (2)'!E13,'GenInfo (2)'!MR13," ")," ") | MT13: =IFERROR(SMALL($MS$8:$MS$94,ROWS($IL$8:IL13))," ") | MU13: =IFERROR(ROWS($IL$8:IL13)," ") -> 6 | MV13: =IFERROR(IF([1]Checklist!$C$14='GenInfo (2)'!E13,'GenInfo (2)'!MU13," ")," ") | MW13: =IFERROR(SMALL($MV$8:$MV$94,ROWS($IL$8:IL13))," ") | MX13: =IFERROR(ROWS($IL$8:IL13)," ") -> 6 | MY13: =IFERROR(IF([1]Checklist!$C$15='GenInfo (2)'!E13,'GenInfo (2)'!MX13," ")," ") | MZ13: =IFERROR(SMALL($MY$8:$MY$94,ROWS($IL$8:IL13))," ") -> 39 | NA13: =IFERROR(ROWS($IL$8:IL13)," ") -> 6 | NB13: =IFERROR(IF([1]Checklist!$C$16='GenInfo (2)'!E13,'GenInfo (2)'!NA13," ")," ") | NC13: =IFERROR(SMALL($NB$8:$NB$94,ROWS($IL$8:IL13))," ") | ND13: =IFERROR(ROWS($IL$8:IL13)," ") -> 6 | NE13: =IFERROR(IF([1]Checklist!$C$17='GenInfo (2)'!E13,'GenInfo (2)'!ND13," ")," ") | NF13: =IFERROR(SMALL($NE$8:$NE$94,ROWS($IL$8:IL13))," ")
A14: x | B14: 45 | C14: Sample06 | D14: Student06 | E14: Asn Preparatory Institute | F14: Z5558985 | G14: Enrolled | I14: SSample06@asn.com | J14: 773-555-0006 | L14: 43888 | M14: 43889 | O14: 43891 | V14: 43921 | W14: Current | AB14: Michael Johnson | AC14: 773-429-9373 | AD14: michael.johnson@ucanchicago.org | AE14: UCAN | AF14: 10046 S. Western | AH14: Chicago | AI14: IL | AJ14: 60643 | AL14: =IFERROR(DATEDIF(AN14,V14,"y"),"") -> 18 | AM14: =IFERROR(DATEDIF($AN14,TODAY(),"y"),"") -> 20 | AN14: 37187 | AO14: =IFERROR(DATEDIF(TODAY(),EDATE(AN14,(12*21)),"m"),"") -> 8 | AP14: M | AQ14: African American | AR14: Foster home | AT14: 150 | AU14: 10 | AV14: 8 | AW14: 730 | AX14: GED | AY14: Yes | AZ14: No | BA14: No | BE14: =IFERROR(COUNTIF(CI14,">0")+COUNTIF(CS14,">0")+COUNTIF(DC14,">0")+COUNTIF(DM14,">0")+COUNTIF(DW14,">0")+COUNTIF(EG14,">0")," ") -> 0 | BF14: =IFERROR(COUNTIF(CJ14,">0")+COUNTIF(CT14,">0")+COUNTIF(DD14,">0")+COUNTIF(DN14,">0")+COUNTIF(DX14,">0")+COUNTIF(EH14,">0")," ") -> 0 | BG14: =IFERROR(COUNTIF(CK14,"<49.5%")+COUNTIF(CU14,"<49.5%")+COUNTIF(DE14,"<49.5%")+COUNTIF(DO14,"<49.5%")+COUNTIF(DY14,"<49.5%")+COUNTIF(EI14,"<49.5%")," ") -> 0 | BH14: =IFERROR(AVERAGE(CK14,CU14,DE14,DO14,DY14,EI14)," ") | BI14: =IFERROR(BG14/BE14," ") | BJ14: =IFERROR(COUNTIF(CN14,">0")+COUNTIF(CW14,">0")+COUNTIF(DH14,">0")+COUNTIF(DR14,">0")+COUNTIF(EB14,">0")+COUNTIF(EL14,">0")," ") -> 0 | BK14: =IFERROR(BJ14/BE14," ") | BL14: =IFERROR(SUM(BV14,CD14,CN14,CW14,DH14,DR14,EB14,EL14),"") -> 0 | BM14: =IFERROR(SUM(BW14,CE14,CO14,CX14,DI14,DS14,EC14,EM14),"") -> 0 | BS14: =IFERROR(BR14/BQ14," ") | BV14: 0 | BW14: 0 | CC14: =IFERROR(CB14/CA14," ") | CE14: 0 | CK14: =IFERROR(CJ14/CI14," ") | CO14: 0 | CU14: =IFERROR(CT14/CS14," ") | CY14: 0 | DE14: =IFERROR(DD14/DC14," ") | DI14: 0 | DO14: =IFERROR(DN14/DM14," ") | DS14: 0 | DY14: =IFERROR(DX14/DW14," ") | DZ14: 0 | EA14: 0 | EB14: 0 | EC14: 0 | EI14: =IFERROR(EH14/EG14," ") | EJ14: 0 | EK14: 0 | EL14: 0 | EM14: 0 | EQ14: 13 | ER14: 13 | ES14: =IFERROR(ER14/EQ14," ") -> 1 | ET14: 0 | EV14: 0 | EW14: 0 | FC14: =IFERROR(FB14/FA14," ") | FH14: =SUM(FD14:FG14) -> 0 | FN14: =IFERROR(FM14/FL14," ") | FS14: =SUM(FO14:FR14) -> 0 | FY14: =IFERROR(FX14/FW14," ") | GD14: =SUM(FZ14:GC14) -> 0 | GG14: GED | GK14: =IFERROR(SUM(GH14:GJ14)," ") -> 0 | GN14: =IFERROR(SUM(GL14:GM14)," ") -> 0 | GO14: =IFERROR(GF14+GK14+GN14," ") | GQ14: x | GR14: x | GS14: x | GT14: x | GU14: x | GV14: x | GW14: x | GX14: x | GY14: n/a | GZ14: n/a | HA14: GED | HB14: GED | HG14: x | HL14: =IFERROR(IF(OR(IQ14>0,IR14>0,IS14>0),"x",""),"") | HM14: =IFERROR(IF(OR(IT14>0,IU14>0,IV14>0),"x",""),"") | HN14: n/a | HO14: =IFERROR(IF(OR(JE14>0,JF14>0,JG14>0,JH14>0),"x",""),"") | HP14: =IFERROR(IF(OR(JI14>0,JJ14>0,JK14>0),"x",""),"") | HQ14: n/a | HS14: GED | HT14: GED | HU14: GED | HV14: GED | HX14: GED | HY14: GED | IC14: x | JA14: =COUNTIF(IO14:IZ14,">=0.0") -> 0 | JP14: =COUNTIF(JD14:JO14,">=0.0") -> 0 | JQ14: =JJ14-JI14 -> 0 | LN14: =IFERROR(ROWS($IL$8:IL14)," ") -> 7 | LO14: =IFERROR(IF([1]Checklist!$C$3='GenInfo (2)'!E14,'GenInfo (2)'!LN14," ")," ") | LP14: =IFERROR(SMALL($LO$8:$LO$94,ROWS($IL$8:IL14))," ") | LQ14: =IFERROR(ROWS($IL$8:IL14)," ") -> 7 | LR14: =IFERROR(IF([1]Checklist!$C$4='GenInfo (2)'!E14,'GenInfo (2)'!LQ14," ")," ") -> 7 | LS14: =IFERROR(SMALL($LR$8:$LR$94,ROWS($IL$8:IL14))," ") | LT14: =IFERROR(ROWS($IL$8:IL14)," ") -> 7 | LU14: =IFERROR(IF([1]Checklist!$C$5='GenInfo (2)'!E14,'GenInfo (2)'!LT14," ")," ") | LV14: =IFERROR(SMALL($LU$8:$LU$94,ROWS($IL$8:IL14))," ") | LW14: =IFERROR(ROWS($IL$8:IL14)," ") -> 7 | LX14: =IFERROR(IF([1]Checklist!$C$6='GenInfo (2)'!E14,'GenInfo (2)'!LW14," ")," ") | LY14: =IFERROR(SMALL($LX$8:$LX$94,ROWS($IL$8:IL14))," ") | LZ14: =IFERROR(ROWS($IL$8:IL14)," ") -> 7 | MA14: =IFERROR(IF([1]Checklist!$C$7='GenInfo (2)'!E14,'GenInfo (2)'!LZ14," ")," ") | MB14: =IFERROR(SMALL($MA$8:$MA$94,ROWS($IL$8:IL14))," ") | MC14: =IFERROR(ROWS($IL$8:IL14)," ") -> 7 | MD14: =IFERROR(IF([1]Checklist!$C$8='GenInfo (2)'!E14,'GenInfo (2)'!MC14," ")," ") | ME14: =IFERROR(SMALL($MD$8:$MD$94,ROWS($IL$8:IL14))," ") | MF14: =IFERROR(ROWS($IL$8:IL14)," ") -> 7 | MG14: =IFERROR(IF([1]Checklist!$C$9='GenInfo (2)'!E14,'GenInfo (2)'!MF14," ")," ") | MH14: =IFERROR(SMALL($MG$8:$MG$94,ROWS($IL$8:IL14))," ") | MI14: =IFERROR(ROWS($IL$8:$IL14)," ") -> 7 | MJ14: =IFERROR(IF([1]Checklist!$C$10='GenInfo (2)'!E14,'GenInfo (2)'!MI14," ")," ") | MK14: =IFERROR(SMALL($MJ$8:$MJ$94,ROWS($IL$8:IL14))," ") | ML14: =IFERROR(ROWS($IL$8:IL14)," ") -> 7 | MM14: =IFERROR(IF([1]Checklist!$C$11='GenInfo (2)'!E14,'GenInfo (2)'!ML14," ")," ") | MN14: =IFERROR(SMALL($MM$8:$MM$94,ROWS($IL$8:IL14))," ") | MO14: =IFERROR(ROWS($IL$8:IL14)," ") -> 7 | MP14: =IFERROR(IF([1]Checklist!$C$12='GenInfo (2)'!E14,'GenInfo (2)'!MO14," ")," ") | MQ14: =IFERROR(SMALL($MP$8:$MP$94,ROWS($IL$8:IL14))," ") | MR14: =IFERROR(ROWS($IL$8:IL14)," ") -> 7 | MS14: =IFERROR(IF([1]Checklist!$C$13='GenInfo (2)'!E14,'GenInfo (2)'!MR14," ")," ") | MT14: =IFERROR(SMALL($MS$8:$MS$94,ROWS($IL$8:IL14))," ") | MU14: =IFERROR(ROWS($IL$8:IL14)," ") -> 7 | MV14: =IFERROR(IF([1]Checklist!$C$14='GenInfo (2)'!E14,'GenInfo (2)'!MU14," ")," ") | MW14: =IFERROR(SMALL($MV$8:$MV$94,ROWS($IL$8:IL14))," ") | MX14: =IFERROR(ROWS($IL$8:IL14)," ") -> 7 | MY14: =IFERROR(IF([1]Checklist!$C$15='GenInfo (2)'!E14,'GenInfo (2)'!MX14," ")," ") | MZ14: =IFERROR(SMALL($MY$8:$MY$94,ROWS($IL$8:IL14))," ") -> 40 | NA14: =IFERROR(ROWS($IL$8:IL14)," ") -> 7 | NB14: =IFERROR(IF([1]Checklist!$C$16='GenInfo (2)'!E14,'GenInfo (2)'!NA14," ")," ") | NC14: =IFERROR(SMALL($NB$8:$NB$94,ROWS($IL$8:IL14))," ") | ND14: =IFERROR(ROWS($IL$8:IL14)," ") -> 7 | NE14: =IFERROR(IF([1]Checklist!$C$17='GenInfo (2)'!E14,'GenInfo (2)'!ND14," ")," ") | NF14: =IFERROR(SMALL($NE$8:$NE$94,ROWS($IL$8:IL14))," ")
A15: x | B15: 49 | C15: Sample07 | D15: Student07 | E15: Association House Hs | F15: S7776988 | G15: Enrolled | I15: SSample07@asn.com | J15: 773-555-0007 | L15: 43788 | M15: 43788 | N15: x | O15: 43770 | R15: Accepted | V15: 43815 | W15: Current | AB15: Ebony Ellis | AC15: (773) 371-6000 | AE15: IDCFS | AL15: =IFERROR(DATEDIF(AN15,V15,"y"),"") -> 16 | AM15: =IFERROR(DATEDIF($AN15,TODAY(),"y"),"") -> 18 | AN15: 37921 | AO15: =IFERROR(DATEDIF(TODAY(),EDATE(AN15,(12*21)),"m"),"") -> 32 | AP15: M | AQ15: African American | AR15: Foster home | AS15: 2 | AT15: 629 | AU15: 15 | AV15: 1 | AW15: 60 | AX15: Freshman | AY15: Unk | AZ15: no | BA15: no | BE15: =IFERROR(COUNTIF(CI15,">0")+COUNTIF(CS15,">0")+COUNTIF(DC15,">0")+COUNTIF(DM15,">0")+COUNTIF(DW15,">0")+COUNTIF(EG15,">0")," ") -> 3 | BF15: =IFERROR(COUNTIF(CJ15,">0")+COUNTIF(CT15,">0")+COUNTIF(DD15,">0")+COUNTIF(DN15,">0")+COUNTIF(DX15,">0")+COUNTIF(EH15,">0")," ") -> 3 | BG15: =IFERROR(COUNTIF(CK15,"<49.5%")+COUNTIF(CU15,"<49.5%")+COUNTIF(DE15,"<49.5%")+COUNTIF(DO15,"<49.5%")+COUNTIF(DY15,"<49.5%")+COUNTIF(EI15,"<49.5%")," ") -> 0 | BH15: =IFERROR(AVERAGE(CK15,CU15,DE15,DO15,DY15,EI15)," ") -> 0.7962963 | BI15: =IFERROR(BG15/BE15," ") -> 0 | BJ15: =IFERROR(COUNTIF(CN15,">0")+COUNTIF(CW15,">0")+COUNTIF(DH15,">0")+COUNTIF(DR15,">0")+COUNTIF(EB15,">0")+COUNTIF(EL15,">0")," ") -> 3 | BK15: =IFERROR(BJ15/BE15," ") -> 1 | BL15: =IFERROR(SUM(BV15,CD15,CN15,CW15,DH15,DR15,EB15,EL15),"") -> 26.75 | BM15: =IFERROR(SUM(BW15,CE15,CO15,CX15,DI15,DS15,EC15,EM15),"") -> 160.5 | BS15: =IFERROR(BR15/BQ15," ") | BT15: 0 | BU15: 0 | BV15: 0 | BW15: 0 | CC15: =IFERROR(CB15/CA15," ") | CD15: 0 | CE15: 0 | CK15: =IFERROR(CJ15/CI15," ") | CL15: 0 | CM15: 0 | CN15: 0 | CO15: 0 | CU15: =IFERROR(CT15/CS15," ") | CV15: 0 | CW15: 0 | CX15: 0 | CY15: 0 | DE15: =IFERROR(DD15/DC15," ") | DF15: 0 | DG15: 0 | DH15: 0 | DI15: 0 | DM15: 15 | DN15: 15 | DO15: =IFERROR(DN15/DM15," ") -> 1 | DP15: 0 | DQ15: 10 | DR15: 10 | DS15: 60 | DW15: 18 | DX15: 11 | DY15: =IFERROR(DX15/DW15," ") -> 0.61111111 | DZ15: 3 | EA15: 4.5 | EB15: 7.5 | EC15: 45 | EG15: 18 | EH15: 14 | EI15: =IFERROR(EH15/EG15," ") -> 0.77777778 | EJ15: 2 | EK15: 7.25 | EL15: 9.25 | EM15: 55.5 | EQ15: 9 | ER15: 3 | ES15: =IFERROR(ER15/EQ15," ") -> 0.33333333 | ET15: 2 | EV15: 2 | EW15: 12 | FC15: =IFERROR(FB15/FA15," ") | FH15: =SUM(FD15:FG15) -> 0 | FN15: =IFERROR(FM15/FL15," ") | FS15: =SUM(FO15:FR15) -> 0 | FY15: =IFERROR(FX15/FW15," ") | GD15: =SUM(FZ15:GC15) -> 0 | GF15: 0 | GG15: Freshman | GK15: =IFERROR(SUM(GH15:GJ15)," ") -> 0 | GN15: =IFERROR(SUM(GL15:GM15)," ") -> 0 | GO15: =IFERROR(GF15+GK15+GN15," ") -> 0 | GQ15: x | GR15: x | GS15: x | GT15: x | GU15: x | GW15: x | GX15: no | GY15: =IFERROR(IF(IN15>0,"X",""),"") -> X | GZ15: =IFERROR(IF(JC15>0,"X",""),"") -> X | HA15: R | HB15: x | HG15: R | HL15: =IFERROR(IF(OR(IQ15>0,IR15>0,IS15>0),"x",""),"") | HM15: =IFERROR(IF(OR(IT15>0,IU15>0,IV15>0),"x",""),"") -> x | HN15: n/a | HO15: =IFERROR(IF(OR(JE15>0,JF15>0,JG15>0,JH15>0),"x",""),"") | HP15: =IFERROR(IF(OR(JI15>0,JJ15>0,JK15>0),"x",""),"") -> x | HQ15: n/a | HT15: x | HU15: x | HX15: x | IA15: m | ID15: 19/20 | IE15: x | IF15: x | IG15: x | IH15: x | II15: x | IJ15: x | IK15: x | IL15: x | IN15: 5.7 | IT15: 5.7 | IU15: 7 | JA15: =COUNTIF(IO15:IZ15,">=0.0") -> 2 | JB15: =IU15-IT15 -> 1.3 | JC15: 4.8 | JI15: 4.8 | JJ15: 6.1 | JP15: =COUNTIF(JD15:JO15,">=0.0") -> 2 | LN15: =IFERROR(ROWS($IL$8:IL15)," ") -> 8 | LO15: =IFERROR(IF([1]Checklist!$C$3='GenInfo (2)'!E15,'GenInfo (2)'!LN15," ")," ") | LP15: =IFERROR(SMALL($LO$8:$LO$94,ROWS($IL$8:IL15))," ") | LQ15: =IFERROR(ROWS($IL$8:IL15)," ") -> 8 | LR15: =IFERROR(IF([1]Checklist!$C$4='GenInfo (2)'!E15,'GenInfo (2)'!LQ15," ")," ") | LS15: =IFERROR(SMALL($LR$8:$LR$94,ROWS($IL$8:IL15))," ") | LT15: =IFERROR(ROWS($IL$8:IL15)," ") -> 8 | LU15: =IFERROR(IF([1]Checklist!$C$5='GenInfo (2)'!E15,'GenInfo (2)'!LT15," ")," ") -> 8 | LV15: =IFERROR(SMALL($LU$8:$LU$94,ROWS($IL$8:IL15))," ") | LW15: =IFERROR(ROWS($IL$8:IL15)," ") -> 8 | LX15: =IFERROR(IF([1]Checklist!$C$6='GenInfo (2)'!E15,'GenInfo (2)'!LW15," ")," ") | LY15: =IFERROR(SMALL($LX$8:$LX$94,ROWS($IL$8:IL15))," ") | LZ15: =IFERROR(ROWS($IL$8:IL15)," ") -> 8 | MA15: =IFERROR(IF([1]Checklist!$C$7='GenInfo (2)'!E15,'GenInfo (2)'!LZ15," ")," ") | MB15: =IFERROR(SMALL($MA$8:$MA$94,ROWS($IL$8:IL15))," ") | MC15: =IFERROR(ROWS($IL$8:IL15)," ") -> 8 | MD15: =IFERROR(IF([1]Checklist!$C$8='GenInfo (2)'!E15,'GenInfo (2)'!MC15," ")," ") | ME15: =IFERROR(SMALL($MD$8:$MD$94,ROWS($IL$8:IL15))," ") | MF15: =IFERROR(ROWS($IL$8:IL15)," ") -> 8 | MG15: =IFERROR(IF([1]Checklist!$C$9='GenInfo (2)'!E15,'GenInfo (2)'!MF15," ")," ") | MH15: =IFERROR(SMALL($MG$8:$MG$94,ROWS($IL$8:IL15))," ") | MI15: =IFERROR(ROWS($IL$8:$IL15)," ") -> 8 | MJ15: =IFERROR(IF([1]Checklist!$C$10='GenInfo (2)'!E15,'GenInfo (2)'!MI15," ")," ") | MK15: =IFERROR(SMALL($MJ$8:$MJ$94,ROWS($IL$8:IL15))," ") | ML15: =IFERROR(ROWS($IL$8:IL15)," ") -> 8 | MM15: =IFERROR(IF([1]Checklist!$C$11='GenInfo (2)'!E15,'GenInfo (2)'!ML15," ")," ") | MN15: =IFERROR(SMALL($MM$8:$MM$94,ROWS($IL$8:IL15))," ") | MO15: =IFERROR(ROWS($IL$8:IL15)," ") -> 8 | MP15: =IFERROR(IF([1]Checklist!$C$12='GenInfo (2)'!E15,'GenInfo (2)'!MO15," ")," ") | MQ15: =IFERROR(SMALL($MP$8:$MP$94,ROWS($IL$8:IL15))," ") | MR15: =IFERROR(ROWS($IL$8:IL15)," ") -> 8 | MS15: =IFERROR(IF([1]Checklist!$C$13='GenInfo (2)'!E15,'GenInfo (2)'!MR15," ")," ") | MT15: =IFERROR(SMALL($MS$8:$MS$94,ROWS($IL$8:IL15))," ") | MU15: =IFERROR(ROWS($IL$8:IL15)," ") -> 8 | MV15: =IFERROR(IF([1]Checklist!$C$14='GenInfo (2)'!E15,'GenInfo (2)'!MU15," ")," ") | MW15: =IFERROR(SMALL($MV$8:$MV$94,ROWS($IL$8:IL15))," ") | MX15: =IFERROR(ROWS($IL$8:IL15)," ") -> 8 | MY15: =IFERROR(IF([1]Checklist!$C$15='GenInfo (2)'!E15,'GenInfo (2)'!MX15," ")," ") | MZ15: =IFERROR(SMALL($MY$8:$MY$94,ROWS($IL$8:IL15))," ") -> 41 | NA15: =IFERROR(ROWS($IL$8:IL15)," ") -> 8 | NB15: =IFERROR(IF([1]Checklist!$C$16='GenInfo (2)'!E15,'GenInfo (2)'!NA15," ")," ") | NC15: =IFERROR(SMALL($NB$8:$NB$94,ROWS($IL$8:IL15))," ") | ND15: =IFERROR(ROWS($IL$8:IL15)," ") -> 8 | NE15: =IFERROR(IF([1]Checklist!$C$17='GenInfo (2)'!E15,'GenInfo (2)'!ND15," ")," ") | NF15: =IFERROR(SMALL($NE$8:$NE$94,ROWS($IL$8:IL15))," ")
